2024-06-11T05:00:07 {"cpu": 0.35986328125, "cpu_total": 16, "cpu_usage": 0.022491455078125, "memory": 3911.0, "memory_total": 12550.0, "memory_usage": 0.31163346613545817, "pipeline_run_id": 15, "pipeline_schedule_id": 1, "pipeline_uuid": "automatic_retraining", "hostname": "5cc8648d24d5", "level": "INFO", "message": "Pipeline automatic_retraining for run 15 in schedule 1 is alive.", "timestamp": 1718082007.540529, "uuid": "4a44d964cc4e4dcea51f667a85ddfe39"}
2024-06-11T05:00:07 {"block_run_id": 54, "block_uuid": "detect_new_data", "pipeline_run_id": 15, "pipeline_schedule_id": 1, "pipeline_uuid": "automatic_retraining", "hostname": "5cc8648d24d5", "level": "INFO", "message": "Execute PipelineRun 15, BlockRun 54: pipeline automatic_retraining block detect_new_data", "timestamp": 1718082007.7596, "uuid": "c0ba66450d4b476f9800f998e0441ba7"}
2024-06-11T05:00:07 {"block_run_id": 54, "block_uuid": "detect_new_data", "pipeline_run_id": 15, "pipeline_schedule_id": 1, "pipeline_uuid": "automatic_retraining", "hostname": "5cc8648d24d5", "level": "EXCEPTION", "message": "BlockRun 54 (block_uuid: detect_new_data) failed.", "timestamp": 1718082007.871886, "uuid": "a1c2e1534ad14a5fb437f120d7ba830c", "error": ["Traceback (most recent call last):\n  File \"<frozen importlib._bootstrap_external>\", line 1372, in _path_importer_cache\nKeyError: '.'\n\nDuring handling of the above exception, another exception occurred:\n\nTraceback (most recent call last):\n  File \"/usr/local/lib/python3.10/site-packages/mage_ai/data_preparation/executors/block_executor.py\", line 647, in execute\n    result = __execute_with_retry()\n  File \"/usr/local/lib/python3.10/site-packages/mage_ai/shared/retry.py\", line 54, in retry_func\n    raise e\n  File \"/usr/local/lib/python3.10/site-packages/mage_ai/shared/retry.py\", line 38, in retry_func\n    return func(*args, **kwargs)\n  File \"/usr/local/lib/python3.10/site-packages/mage_ai/data_preparation/executors/block_executor.py\", line 621, in __execute_with_retry\n    return self._execute(\n  File \"/usr/local/lib/python3.10/site-packages/mage_ai/data_preparation/executors/block_executor.py\", line 1154, in _execute\n    result = self.block.execute_sync(\n  File \"/usr/local/lib/python3.10/site-packages/mage_ai/data_preparation/models/block/__init__.py\", line 1672, in execute_sync\n    return __execute()\n  File \"/usr/local/lib/python3.10/site-packages/mage_ai/data_preparation/models/block/__init__.py\", line 1649, in __execute\n    raise err\n  File \"/usr/local/lib/python3.10/site-packages/mage_ai/data_preparation/models/block/__init__.py\", line 1500, in __execute\n    global_vars = self.enrich_global_vars(\n  File \"/usr/local/lib/python3.10/site-packages/mage_ai/data_preparation/models/block/__init__.py\", line 3560, in enrich_global_vars\n    ) or is_spark_env():\n  File \"/usr/local/lib/python3.10/site-packages/mage_ai/shared/utils.py\", line 177, in is_spark_env\n    return importlib.util.find_spec('pyspark') is not None\n  File \"/usr/local/lib/python3.10/importlib/util.py\", line 103, in find_spec\n    return _find_spec(fullname, parent_path)\n  File \"<frozen importlib._bootstrap>\", line 945, in _find_spec\n  File \"<frozen importlib._bootstrap_external>\", line 1439, in find_spec\n  File \"<frozen importlib._bootstrap_external>\", line 1408, in _get_spec\n  File \"<frozen importlib._bootstrap_external>\", line 1374, in _path_importer_cache\n  File \"<frozen importlib._bootstrap_external>\", line 1350, in _path_hooks\n  File \"<frozen importlib._bootstrap_external>\", line 1632, in path_hook_for_FileFinder\n  File \"<frozen importlib._bootstrap_external>\", line 1505, in __init__\nFileNotFoundError: [Errno 2] No such file or directory\n"], "error_stack": [["  File \"/usr/local/bin/mage\", line 8, in <module>\n    sys.exit(app())\n", "  File \"/usr/local/lib/python3.10/site-packages/typer/main.py\", line 311, in __call__\n    return get_command(self)(*args, **kwargs)\n", "  File \"/usr/local/lib/python3.10/site-packages/click/core.py\", line 1130, in __call__\n    return self.main(*args, **kwargs)\n", "  File \"/usr/local/lib/python3.10/site-packages/typer/core.py\", line 778, in main\n    return _main(\n", "  File \"/usr/local/lib/python3.10/site-packages/typer/core.py\", line 216, in _main\n    rv = self.invoke(ctx)\n", "  File \"/usr/local/lib/python3.10/site-packages/click/core.py\", line 1657, in invoke\n    return _process_result(sub_ctx.command.invoke(sub_ctx))\n", "  File \"/usr/local/lib/python3.10/site-packages/click/core.py\", line 1404, in invoke\n    return ctx.invoke(self.callback, **ctx.params)\n", "  File \"/usr/local/lib/python3.10/site-packages/click/core.py\", line 760, in invoke\n    return __callback(*args, **kwargs)\n", "  File \"/usr/local/lib/python3.10/site-packages/typer/main.py\", line 683, in wrapper\n    return callback(**use_params)  # type: ignore\n", "  File \"/usr/local/lib/python3.10/site-packages/mage_ai/cli/main.py\", line 147, in start\n    start_server(\n", "  File \"/usr/local/lib/python3.10/site-packages/mage_ai/server/server.py\", line 783, in start_server\n    scheduler_manager.start_scheduler()\n", "  File \"/usr/local/lib/python3.10/site-packages/mage_ai/server/scheduler_manager.py\", line 106, in start_scheduler\n    proc.start()\n", "  File \"/usr/local/lib/python3.10/multiprocessing/process.py\", line 121, in start\n    self._popen = self._Popen(self)\n", "  File \"/usr/local/lib/python3.10/multiprocessing/context.py\", line 224, in _Popen\n    return _default_context.get_context().Process._Popen(process_obj)\n", "  File \"/usr/local/lib/python3.10/multiprocessing/context.py\", line 281, in _Popen\n    return Popen(process_obj)\n", "  File \"/usr/local/lib/python3.10/multiprocessing/popen_fork.py\", line 19, in __init__\n    self._launch(process_obj)\n", "  File \"/usr/local/lib/python3.10/multiprocessing/popen_fork.py\", line 71, in _launch\n    code = process_obj._bootstrap(parent_sentinel=child_r)\n", "  File \"/usr/local/lib/python3.10/multiprocessing/process.py\", line 314, in _bootstrap\n    self.run()\n", "  File \"/usr/local/lib/python3.10/multiprocessing/process.py\", line 108, in run\n    self._target(*self._args, **self._kwargs)\n", "  File \"/usr/local/lib/python3.10/site-packages/mage_ai/orchestration/db/process.py\", line 15, in start_session_and_run\n    results = target(*args)\n", "  File \"/usr/local/lib/python3.10/site-packages/mage_ai/server/scheduler_manager.py\", line 58, in run_scheduler\n    LoopTimeTrigger().start()\n", "  File \"/usr/local/lib/python3.10/site-packages/mage_ai/orchestration/triggers/loop_time_trigger.py\", line 14, in start\n    self.run()\n", "  File \"/usr/local/lib/python3.10/site-packages/mage_ai/orchestration/triggers/time_trigger.py\", line 11, in run\n    schedule_all()\n", "  File \"/usr/local/lib/python3.10/site-packages/mage_ai/orchestration/pipeline_scheduler_original.py\", line 1707, in schedule_all\n    PipelineScheduler(r).start()\n", "  File \"/usr/local/lib/python3.10/site-packages/mage_ai/orchestration/db/__init__.py\", line 158, in func_with_rollback\n    return func(*args, **kwargs)\n", "  File \"/usr/local/lib/python3.10/site-packages/mage_ai/orchestration/pipeline_scheduler_original.py\", line 198, in start\n    self.schedule()\n", "  File \"/usr/local/lib/python3.10/site-packages/mage_ai/orchestration/db/__init__.py\", line 158, in func_with_rollback\n    return func(*args, **kwargs)\n", "  File \"/usr/local/lib/python3.10/site-packages/mage_ai/orchestration/pipeline_scheduler_original.py\", line 334, in schedule\n    self.__schedule_blocks(block_runs)\n", "  File \"/usr/local/lib/python3.10/site-packages/mage_ai/orchestration/pipeline_scheduler_original.py\", line 641, in __schedule_blocks\n    job_manager.add_job(\n", "  File \"/usr/local/lib/python3.10/site-packages/mage_ai/orchestration/job_manager.py\", line 20, in add_job\n    self.queue.enqueue(job_id, target, *args, **kwargs)\n", "  File \"/usr/local/lib/python3.10/site-packages/mage_ai/orchestration/queue/process_queue.py\", line 121, in enqueue\n    self.start_worker_pool()\n", "  File \"/usr/local/lib/python3.10/site-packages/mage_ai/orchestration/queue/process_queue.py\", line 198, in start_worker_pool\n    self.worker_pool_proc.start()\n", "  File \"/usr/local/lib/python3.10/multiprocessing/process.py\", line 121, in start\n    self._popen = self._Popen(self)\n", "  File \"/usr/local/lib/python3.10/multiprocessing/context.py\", line 224, in _Popen\n    return _default_context.get_context().Process._Popen(process_obj)\n", "  File \"/usr/local/lib/python3.10/multiprocessing/context.py\", line 281, in _Popen\n    return Popen(process_obj)\n", "  File \"/usr/local/lib/python3.10/multiprocessing/popen_fork.py\", line 19, in __init__\n    self._launch(process_obj)\n", "  File \"/usr/local/lib/python3.10/multiprocessing/popen_fork.py\", line 71, in _launch\n    code = process_obj._bootstrap(parent_sentinel=child_r)\n", "  File \"/usr/local/lib/python3.10/multiprocessing/process.py\", line 314, in _bootstrap\n    self.run()\n", "  File \"/usr/local/lib/python3.10/multiprocessing/process.py\", line 108, in run\n    self._target(*self._args, **self._kwargs)\n", "  File \"/usr/local/lib/python3.10/site-packages/mage_ai/orchestration/queue/process_queue.py\", line 351, in poll_job_and_execute\n    worker.start()\n", "  File \"/usr/local/lib/python3.10/multiprocessing/process.py\", line 121, in start\n    self._popen = self._Popen(self)\n", "  File \"/usr/local/lib/python3.10/multiprocessing/context.py\", line 224, in _Popen\n    return _default_context.get_context().Process._Popen(process_obj)\n", "  File \"/usr/local/lib/python3.10/multiprocessing/context.py\", line 281, in _Popen\n    return Popen(process_obj)\n", "  File \"/usr/local/lib/python3.10/multiprocessing/popen_fork.py\", line 19, in __init__\n    self._launch(process_obj)\n", "  File \"/usr/local/lib/python3.10/multiprocessing/popen_fork.py\", line 71, in _launch\n    code = process_obj._bootstrap(parent_sentinel=child_r)\n", "  File \"/usr/local/lib/python3.10/multiprocessing/process.py\", line 314, in _bootstrap\n    self.run()\n", "  File \"/usr/local/lib/python3.10/site-packages/newrelic/api/background_task.py\", line 117, in wrapper\n    return wrapped(*args, **kwargs)\n", "  File \"/usr/local/lib/python3.10/site-packages/mage_ai/orchestration/queue/process_queue.py\", line 315, in run\n    start_session_and_run(args[1], *args[2], **args[3])\n", "  File \"/usr/local/lib/python3.10/site-packages/mage_ai/orchestration/db/process.py\", line 15, in start_session_and_run\n    results = target(*args)\n", "  File \"/usr/local/lib/python3.10/site-packages/mage_ai/orchestration/pipeline_scheduler_original.py\", line 1232, in run_block\n    return ExecutorFactory.get_block_executor(\n", "  File \"/usr/local/lib/python3.10/site-packages/mage_ai/data_preparation/executors/block_executor.py\", line 682, in execute\n    on_failure(\n", "  File \"/usr/local/lib/python3.10/site-packages/mage_ai/orchestration/db/__init__.py\", line 158, in func_with_rollback\n    return func(*args, **kwargs)\n", "  File \"/usr/local/lib/python3.10/site-packages/mage_ai/orchestration/pipeline_scheduler_original.py\", line 465, in on_block_failure\n    self.logger.exception(\n", "  File \"/usr/local/lib/python3.10/site-packages/mage_ai/data_preparation/logging/logger.py\", line 30, in exception\n    self.__send_message('exception', message, **kwargs)\n", "  File \"/usr/local/lib/python3.10/site-packages/mage_ai/data_preparation/logging/logger.py\", line 65, in __send_message\n    data['error_stack'] = traceback.format_stack(),\n"]], "error_stacktrace": ["[Errno 2] No such file or directory"]}
Traceback (most recent call last):
  File "<frozen importlib._bootstrap_external>", line 1372, in _path_importer_cache
KeyError: '.'

During handling of the above exception, another exception occurred:

Traceback (most recent call last):
  File "/usr/local/lib/python3.10/site-packages/mage_ai/data_preparation/executors/block_executor.py", line 647, in execute
    result = __execute_with_retry()
  File "/usr/local/lib/python3.10/site-packages/mage_ai/shared/retry.py", line 54, in retry_func
    raise e
  File "/usr/local/lib/python3.10/site-packages/mage_ai/shared/retry.py", line 38, in retry_func
    return func(*args, **kwargs)
  File "/usr/local/lib/python3.10/site-packages/mage_ai/data_preparation/executors/block_executor.py", line 621, in __execute_with_retry
    return self._execute(
  File "/usr/local/lib/python3.10/site-packages/mage_ai/data_preparation/executors/block_executor.py", line 1154, in _execute
    result = self.block.execute_sync(
  File "/usr/local/lib/python3.10/site-packages/mage_ai/data_preparation/models/block/__init__.py", line 1672, in execute_sync
    return __execute()
  File "/usr/local/lib/python3.10/site-packages/mage_ai/data_preparation/models/block/__init__.py", line 1649, in __execute
    raise err
  File "/usr/local/lib/python3.10/site-packages/mage_ai/data_preparation/models/block/__init__.py", line 1500, in __execute
    global_vars = self.enrich_global_vars(
  File "/usr/local/lib/python3.10/site-packages/mage_ai/data_preparation/models/block/__init__.py", line 3560, in enrich_global_vars
    ) or is_spark_env():
  File "/usr/local/lib/python3.10/site-packages/mage_ai/shared/utils.py", line 177, in is_spark_env
    return importlib.util.find_spec('pyspark') is not None
  File "/usr/local/lib/python3.10/importlib/util.py", line 103, in find_spec
    return _find_spec(fullname, parent_path)
  File "<frozen importlib._bootstrap>", line 945, in _find_spec
  File "<frozen importlib._bootstrap_external>", line 1439, in find_spec
  File "<frozen importlib._bootstrap_external>", line 1408, in _get_spec
  File "<frozen importlib._bootstrap_external>", line 1374, in _path_importer_cache
  File "<frozen importlib._bootstrap_external>", line 1350, in _path_hooks
  File "<frozen importlib._bootstrap_external>", line 1632, in path_hook_for_FileFinder
  File "<frozen importlib._bootstrap_external>", line 1505, in __init__
FileNotFoundError: [Errno 2] No such file or directory
2024-06-11T05:00:07 {"cpu": 0.35986328125, "cpu_total": 16, "cpu_usage": 0.022491455078125, "memory": 3932.0, "memory_total": 12550.0, "memory_usage": 0.31330677290836656, "pipeline_run_id": 15, "pipeline_schedule_id": 1, "pipeline_uuid": "automatic_retraining", "hostname": "5cc8648d24d5", "level": "INFO", "message": "Pipeline automatic_retraining for run 15 in schedule 1 is alive.", "timestamp": 1718082007.968188, "uuid": "982477800cdd497f9c20df6f0f9f758b"}
2024-06-11T05:00:17 {"cpu": 0.35595703125, "cpu_total": 16, "cpu_usage": 0.022247314453125, "memory": 3910.0, "memory_total": 12550.0, "memory_usage": 0.3115537848605578, "pipeline_run_id": 15, "pipeline_schedule_id": 1, "pipeline_uuid": "automatic_retraining", "hostname": "5cc8648d24d5", "level": "INFO", "message": "Pipeline automatic_retraining for run 15 in schedule 1 is alive.", "timestamp": 1718082017.413386, "uuid": "42560cb6525241c8a73e25cb1f96c59d"}
